#VRML_SIM R2019a utf8
WorldInfo {
}
Viewpoint {
  orientation -0.7230685309293374 0.6788122007119469 0.128007405036947 0.45725221232793434
  position 0.7507024831608891 1.3834152470152956 3.015708917916869
}
TexturedBackground {
}
TexturedBackgroundLight {
}
Floor {
}
Solid {
  translation 0 -0.03 0
  rotation 1 0 0 0
  children [
    DEF Col Group {
      children [
        DEF A Group {
          children [
            Transform {
              translation 0 0.5 0
              rotation 1 0 0 0.3927
              children [
                DEF POSTE Shape {
                  appearance Appearance {
                    material Material {
                      diffuseColor 1 0 0
                    }
                  }
                  geometry Cylinder {
                    height 1
                    radius 0.035
                  }
                }
              ]
            }
            Transform {
              translation 0 0.5 0.4
              rotation 1 0 0 -0.3926996938995747
              children [
                USE POSTE
              ]
            }
            Transform {
              translation 0 0.5 0.2
              rotation 1 0 0 1.5708
              children [
                DEF POSTE_middle Shape {
                  appearance Appearance {
                    material Material {
                      diffuseColor 0 1 0
                    }
                  }
                  geometry Cylinder {
                    height 0.4
                    radius 0.035
                  }
                }
              ]
            }
          ]
        }
        DEF A2 Group {
          children [
            Transform {
              translation 1 0.5 0
              rotation 1 0 0 0.3926996938995747
              children [
                DEF POSTE Shape {
                  appearance Appearance {
                    material Material {
                      diffuseColor 1 0 0
                    }
                  }
                  geometry Cylinder {
                    height 1
                    radius 0.035
                  }
                }
              ]
            }
            Transform {
              translation 1 0.5 0.4
              rotation 1 0 0 -0.3926996938995747
              children [
                DEF POSTE Shape {
                  appearance Appearance {
                    material Material {
                      diffuseColor 1 0 0
                    }
                  }
                  geometry Cylinder {
                    height 1
                    radius 0.035
                  }
                }
              ]
            }
            Transform {
              translation 1 0.5 0.2
              rotation 1 0 0 1.5707996938995747
              children [
                DEF POSTE_middle Shape {
                  appearance Appearance {
                    material Material {
                      diffuseColor 0 1 0
                    }
                  }
                  geometry Cylinder {
                    height 0.4
                    radius 0.035
                  }
                }
              ]
            }
            Transform {
              translation 0.5 0.93 0.2
              rotation 0 0 1 1.5707996938995747
              children [
                DEF POSTE Shape {
                  appearance Appearance {
                    material Material {
                      diffuseColor 1 0 0
                    }
                  }
                  geometry Cylinder {
                    height 1
                    radius 0.035
                  }
                }
              ]
            }
          ]
        }
        HingeJoint {
          jointParameters HingeJointParameters {
            axis 0 1 0
            anchor 0.5 0.875 0.2
            minStop -0.7853
            maxStop 0.7853
            staticFriction 1
          }
          endPoint Solid {
            translation 0.5 0.8749686080307111 0.2
            children [
              DEF box Shape {
                appearance Appearance {
                  material Material {
                    diffuseColor 0 0 1
                  }
                }
                geometry Box {
                  size 0.3 0.05 0.1
                }
              }
              HingeJoint {
                jointParameters HingeJointParameters {
                  minStop -0.785
                  maxStop 0.785
                  staticFriction 0.5
                }
                endPoint Solid {
                  translation 0 -0.20003137646770786 0
                  rotation 1 0 0 0
                  children [
                    DEF Ball Group {
                      children [
                        Shape {
                          appearance Appearance {
                            material Material {
                              diffuseColor 0.5 0 1
                            }
                          }
                          geometry Box {
                            size 0.035 0.5 0.035
                          }
                        }
                        Transform {
                          translation 0 -0.38 0
                          children [
                            Shape {
                              appearance Appearance {
                                material Material {
                                  diffuseColor 0.5 0 1
                                }
                              }
                              geometry Sphere {
                                radius 0.15
                              }
                            }
                          ]
                        }
                      ]
                    }
                  ]
                  boundingObject USE Ball
                  physics Physics {
                  }
                  linearVelocity -4.084500214440734e-10 -1.4275305870695974e-05 0
                  angularVelocity 0 0 8.237795712420598e-12
                }
              }
            ]
            boundingObject USE box
            physics Physics {
            }
            linearVelocity -2.065266598433313e-10 -7.087637619936989e-06 0
            angularVelocity 0 0 4.1173638635175735e-12
          }
        }
      ]
    }
  ]
  boundingObject USE A2
}
Solid {
  translation 0 -0.03 0
  name "solid(1)"
  boundingObject USE A
}
